<?xml version="1.0" ?>
<robot name="turtlebot3_burger" xmlns:xacro="http://ros.org/wiki/xacro">
  <xacro:include filename="$(find turtlebot3_description)/urdf/common_properties.xacro"/>
  <xacro:include filename="$(find turtlebot3_description)/urdf/turtlebot3_burger.gazebo.xacro"/>

  <link name="base_footprint"/>

  <joint name="base_joint" type="fixed">
    <parent link="base_footprint"/>
    <child link="base_link"/>
    <origin xyz="0.0 0.0 0.028" rpy="0 0 0"/>
  </joint>

  <link name="base_link">
    <visual>
      <origin xyz="-0.0896 0 0.0" rpy="0 0 0"/>
      <geometry>
        <mesh filename="package://turtlebot3_description/meshes/bases/burger_base.stl" scale="0.0028 0.0028 0.0028"/>
      </geometry>
      <material name="light_black"/>
    </visual>

    <collision>
      <origin xyz="-0.0896 0 0.196" rpy="0 0 0"/>
      <geometry>
        <box size="0.392 0.392 0.4004"/>
      </geometry>
    </collision>

    <inertial>
      <origin xyz="0 0 0" rpy="0 0 0"/>
      <mass value="103.2125"/>
      <inertia ixx="0.2765" ixy="-1.53675e-03" ixz="4.36725e-03"
               iyy="0.2649125" iyz="-6.2651125e-04"
               izz="0.2508" />
    </inertial>
  </link>
   <joint name="wheel_left_joint" type="continuous">
  <!-- <joint name="wheel_left_joint" type="fixed"> -->
     <parent link="base_link"/>
    <child link="wheel_left_link"/>
    <origin xyz="0.0 0.224 0.0644" rpy="-1.57 0 0"/>
    <axis xyz="0 0 1"/>
  </joint>

  <link name="wheel_left_link">
    <visual>
      <origin xyz="0 0 0" rpy="1.57 0 0"/>
      <geometry>
        <mesh filename="package://turtlebot3_description/meshes/wheels/left_tire.stl" scale="0.0028 0.0028 0.0028"/>
      </geometry>
      <material name="dark"/>
    </visual>

    <collision>
      <origin xyz="0 0 0" rpy="0 0 0"/>
      <geometry>
        <cylinder length="0.0504" radius="0.0924"/>
      </geometry>
    </collision>

    <inertial>
      <origin xyz="0 0 0" />
      <mass value="3.5623675" />
      <inertia ixx="1.3969475e-03" ixy="-5.296222875e-09" ixz="-7.4225e-07"
               iyy="1.399051625e-03" iyz="-1.800013375e-09"
               izz="2.58906975e-03" />
      </inertial>
  </link>

  <joint name="wheel_right_joint" type="continuous">
  <!-- <joint name="wheel_right_joint" type="fixed"> -->
    <parent link="base_link"/>
    <child link="wheel_right_link"/>
    <origin xyz="0.0 -0.224 0.0644" rpy="-1.57 0 0"/>
    <axis xyz="0 0 1"/>
  </joint>

  <link name="wheel_right_link">
    <visual>
      <origin xyz="0 0 0" rpy="1.57 0 0"/>
      <geometry>
        <mesh filename="package://turtlebot3_description/meshes/wheels/right_tire.stl" scale="0.0028 0.0028 0.0028"/>
      </geometry>
      <material name="dark"/>
    </visual>

    <collision>
      <origin xyz="0 0 0" rpy="0 0 0"/>
      <geometry>
        <cylinder length="0.0504" radius="0.0924"/>
      </geometry>
    </collision>

    <inertial>
      <origin xyz="0 0 0" />
      <mass value="3.5623675" />
      <inertia ixx="1.3969475e-03" ixy="-5.296222875e-09" ixz="-7.4225e-07"
               iyy="1.399051625e-03" iyz="-1.800013375e-09"
               izz="2.58906975e-03" />
      </inertial>
  </link>

  <joint name="caster_back_joint" type="fixed">
    <parent link="base_link"/>
    <child link="caster_back_link"/>
    <origin xyz="-0.2268 0 -0.0112" rpy="-1.57 0 0"/>
  </joint>

  <link name="caster_back_link">
    <collision>
      <origin xyz="0 0.0028 0" rpy="0 0 0"/>
      <geometry>
        <box size="0.084 0.0252 0.056"/>
      </geometry>
    </collision>
    <visual>
      <origin xyz="0 0.0028 0" rpy="0 0 0"/>
      <geometry>
        <box size="0.084 0.0252 0.056"/>
      </geometry>
    </visual>

    <inertial>
      <origin xyz="0 0 0" />
      <mass value="6.25" />
      <inertia ixx="0.125" ixy="0.0" ixz="0.0"
               iyy="0.125" iyz="0.0"
               izz="0.125" />
    </inertial>
  </link>

  <joint name="imu_joint" type="fixed">
    <parent link="base_link"/>
    <child link="imu_link"/>
    <origin xyz="-0.0896 0 0.1904" rpy="0 0 0"/>
  </joint>

  <link name="imu_link"/>

  <joint name="scan_joint" type="fixed">
    <parent link="base_link"/>
    <child link="base_scan"/>
    <origin xyz="-0.0896 0 0.4816" rpy="0 0 0"/>
  </joint>

  <link name="base_scan">
    <visual>
      <origin xyz="0 0 0.0" rpy="0 0 0"/>
      <geometry>
        <mesh filename="package://turtlebot3_description/meshes/sensors/lds.stl" scale="0.0028 0.0028 0.0028"/>
      </geometry>
      <material name="dark"/>
    </visual>

    <collision>
      <origin xyz="0.042 0 -0.0182" rpy="0 0 0"/>
      <geometry>
        <cylinder length="0.0882" radius="0.154"/>
      </geometry>
    </collision>

    <inertial>
      <mass value="0.57" />
      <origin xyz="0 0 0" />
      <inertia ixx="0.005" ixy="0.0" ixz="0.0"
               iyy="0.005" iyz="0.0"
               izz="0.005" />
    </inertial>
  </link>

  <joint name="camera_joint" type="fixed">
    <parent link="base_link"/>
    <child link="camera_link"/>
    <origin xyz="0.056 0 0.4788" rpy="0 0 0"/>
  </joint>



<link name='camera_link'>
<!-- <inertial>
  <origin xyz="0 0 0.0" rpy="0 0 0"/>
  <inertia ixx="0.005" ixy="0.0" ixz="0.0"
           iyy="0.005" iyz="0.0"
           izz="0.005" />
  <mass value="0.02" />
</inertial> -->

<visual name='camera_visual'>
    <origin xyz="0.056 -0.028 -0.056" rpy="0 1.57 0"/>
  <geometry>
    <mesh filename="package://turtlebot3_description/meshes/sensors/ras_cam.dae" scale="2.8 2.8 2.8"/>
  </geometry>
</visual>

<collision name='camera_collision'>
  <pose frame=''>0.056 -0.028 0.294 0 -0 0</pose>
  <geometry>
     <box size="0.0084 0.084 0.07"/>
  </geometry>
</collision>
</link>

  <joint name="camera_joint_2" type="fixed">
    <parent link="base_link"/>
    <child link="camera_link_2"/>
    <origin xyz="0.056 0 0.4788" rpy="0 0 0.785"/>
  </joint>



<link name='camera_link_2'>
<!-- <inertial>
  <origin xyz="0 0 0.0" rpy="0 0 0"/>
  <inertia ixx="0.005" ixy="0.0" ixz="0.0"
           iyy="0.005" iyz="0.0"
           izz="0.005" />
  <mass value="0.02" />
</inertial> -->

<visual name='camera_visual_2'>
    <origin xyz="0.056 -0.028 -0.056" rpy="0 1.57 0"/>
  <geometry>
    <mesh filename="package://turtlebot3_description/meshes/sensors/ras_cam.dae" scale="2.8 2.8 2.8"/>
  </geometry>
</visual>

<collision name='camera_collision_2'>
  <pose frame=''>0.056 -0.028 -0.056 0 -0 0</pose>
  <geometry>
     <box size="0.0084 0.084 0.07"/>
  </geometry>
</collision>
</link>


  <joint name="camera_joint_3" type="fixed">
    <parent link="base_link"/>
    <child link="camera_link_3"/>
    <origin xyz="0.056 0 0.4788" rpy="0 0 -0.785"/>
  </joint>



<link name='camera_link_3'>
<!-- <inertial>
  <origin xyz="0 0 0.0" rpy="0 0 0"/>
  <inertia ixx="0.005" ixy="0.0" ixz="0.0"
           iyy="0.005" iyz="0.0"
           izz="0.005" />
  <mass value="0.02" />
</inertial> -->

<visual name='camera_visual_3'>
    <origin xyz="0.056 -0.028 -0.056" rpy="0 1.57 0"/>
  <geometry>
    <mesh filename="package://turtlebot3_description/meshes/sensors/ras_cam.dae" scale="2.8 2.8 2.8"/>
  </geometry>
</visual>

<collision name='camera_collision_3'>
  <pose frame=''>0.056 -0.028 -0.056 0 -0 0</pose>
  <geometry>
     <box size="0.0084 0.084 0.07"/>
  </geometry>
</collision>
</link>

</robot>
